[2025-02-08T03:44:29.507+0000] {local_task_job_runner.py:120} INFO - ::group::Pre task execution logs
[2025-02-08T03:44:29.544+0000] {taskinstance.py:2076} INFO - Dependencies all met for dep_context=non-requeueable deps ti=<TaskInstance: test_mysql_connection.creat_table manual__2025-02-08T03:44:28.946855+00:00 [queued]>
[2025-02-08T03:44:29.555+0000] {taskinstance.py:2076} INFO - Dependencies all met for dep_context=requeueable deps ti=<TaskInstance: test_mysql_connection.creat_table manual__2025-02-08T03:44:28.946855+00:00 [queued]>
[2025-02-08T03:44:29.555+0000] {taskinstance.py:2306} INFO - Starting attempt 1 of 1
[2025-02-08T03:44:29.572+0000] {taskinstance.py:2330} INFO - Executing <Task(MySqlOperator): creat_table> on 2025-02-08 03:44:28.946855+00:00
[2025-02-08T03:44:29.577+0000] {standard_task_runner.py:63} INFO - Started process 510 to run task
[2025-02-08T03:44:29.582+0000] {standard_task_runner.py:90} INFO - Running: ['***', 'tasks', 'run', 'test_mysql_connection', 'creat_table', 'manual__2025-02-08T03:44:28.946855+00:00', '--job-id', '11', '--raw', '--subdir', 'DAGS_FOLDER/test.py', '--cfg-path', '/tmp/tmpsy4hkrua']
[2025-02-08T03:44:29.584+0000] {standard_task_runner.py:91} INFO - Job 11: Subtask creat_table
[2025-02-08T03:44:29.636+0000] {task_command.py:426} INFO - Running <TaskInstance: test_mysql_connection.creat_table manual__2025-02-08T03:44:28.946855+00:00 [running]> on host d6e46d5d7f5c
[2025-02-08T03:44:29.713+0000] {taskinstance.py:2648} INFO - Exporting env vars: AIRFLOW_CTX_DAG_OWNER='***' AIRFLOW_CTX_DAG_ID='test_mysql_connection' AIRFLOW_CTX_TASK_ID='creat_table' AIRFLOW_CTX_EXECUTION_DATE='2025-02-08T03:44:28.946855+00:00' AIRFLOW_CTX_TRY_NUMBER='1' AIRFLOW_CTX_DAG_RUN_ID='manual__2025-02-08T03:44:28.946855+00:00'
[2025-02-08T03:44:29.714+0000] {taskinstance.py:430} INFO - ::endgroup::
[2025-02-08T03:44:29.728+0000] {sql.py:276} INFO - Executing: CREATE TABLE customersabcd(customer_id varchar(64), name varchar(64))
[2025-02-08T03:44:29.736+0000] {base.py:84} INFO - Using connection ID 'mysql' for task execution.
[2025-02-08T03:44:29.743+0000] {base.py:84} INFO - Using connection ID 'mysql' for task execution.
[2025-02-08T03:44:33.465+0000] {taskinstance.py:441} INFO - ::group::Post task execution logs
[2025-02-08T03:44:33.466+0000] {taskinstance.py:2905} ERROR - Task failed with exception
Traceback (most recent call last):
  File "/home/airflow/.local/lib/python3.10/site-packages/airflow/models/taskinstance.py", line 465, in _execute_task
    result = _execute_callable(context=context, **execute_callable_kwargs)
  File "/home/airflow/.local/lib/python3.10/site-packages/airflow/models/taskinstance.py", line 432, in _execute_callable
    return execute_callable(context=context, **execute_callable_kwargs)
  File "/home/airflow/.local/lib/python3.10/site-packages/airflow/models/baseoperator.py", line 401, in wrapper
    return func(self, *args, **kwargs)
  File "/home/airflow/.local/lib/python3.10/site-packages/airflow/providers/common/sql/operators/sql.py", line 282, in execute
    output = hook.run(
  File "/home/airflow/.local/lib/python3.10/site-packages/airflow/providers/common/sql/hooks/sql.py", line 431, in run
    with self._create_autocommit_connection(autocommit) as conn:
  File "/usr/local/lib/python3.10/contextlib.py", line 135, in __enter__
    return next(self.gen)
  File "/home/airflow/.local/lib/python3.10/site-packages/airflow/providers/common/sql/hooks/sql.py", line 551, in _create_autocommit_connection
    with closing(self.get_conn()) as conn:
  File "/home/airflow/.local/lib/python3.10/site-packages/airflow/providers/mysql/hooks/mysql.py", line 196, in get_conn
    return MySQLdb.connect(**conn_config)
  File "/home/airflow/.local/lib/python3.10/site-packages/MySQLdb/__init__.py", line 121, in Connect
    return Connection(*args, **kwargs)
  File "/home/airflow/.local/lib/python3.10/site-packages/MySQLdb/connections.py", line 195, in __init__
    super().__init__(*args, **kwargs2)
MySQLdb.OperationalError: (2005, "Unknown server host 'mysql' (-2)")
[2025-02-08T03:44:33.476+0000] {taskinstance.py:1206} INFO - Marking task as FAILED. dag_id=test_mysql_connection, task_id=creat_table, run_id=manual__2025-02-08T03:44:28.946855+00:00, execution_date=20250208T034428, start_date=20250208T034429, end_date=20250208T034433
[2025-02-08T03:44:33.612+0000] {standard_task_runner.py:110} ERROR - Failed to execute job 11 for task creat_table ((2005, "Unknown server host 'mysql' (-2)"); 510)
[2025-02-08T03:44:33.620+0000] {local_task_job_runner.py:240} INFO - Task exited with return code 1
[2025-02-08T03:44:33.635+0000] {taskinstance.py:3503} INFO - 0 downstream tasks scheduled from follow-on schedule check
[2025-02-08T03:44:33.639+0000] {local_task_job_runner.py:222} INFO - ::endgroup::
