[2025-02-08T05:06:33.027+0000] {local_task_job_runner.py:120} INFO - ::group::Pre task execution logs
[2025-02-08T05:06:33.058+0000] {taskinstance.py:2076} INFO - Dependencies all met for dep_context=non-requeueable deps ti=<TaskInstance: e_commerce_dw_etl.extract.extract_and_load_to_staging scheduled__2024-11-25T00:00:00+00:00 [queued]>
[2025-02-08T05:06:33.068+0000] {taskinstance.py:2076} INFO - Dependencies all met for dep_context=requeueable deps ti=<TaskInstance: e_commerce_dw_etl.extract.extract_and_load_to_staging scheduled__2024-11-25T00:00:00+00:00 [queued]>
[2025-02-08T05:06:33.069+0000] {taskinstance.py:2306} INFO - Starting attempt 1 of 1
[2025-02-08T05:06:33.083+0000] {taskinstance.py:2330} INFO - Executing <Task(PythonOperator): extract.extract_and_load_to_staging> on 2024-11-25 00:00:00+00:00
[2025-02-08T05:06:33.088+0000] {standard_task_runner.py:63} INFO - Started process 290 to run task
[2025-02-08T05:06:33.091+0000] {standard_task_runner.py:90} INFO - Running: ['***', 'tasks', 'run', 'e_commerce_dw_etl', 'extract.extract_and_load_to_staging', 'scheduled__2024-11-25T00:00:00+00:00', '--job-id', '45', '--raw', '--subdir', 'DAGS_FOLDER/e_commerce_dw_dag.py', '--cfg-path', '/tmp/tmpic9x_ozi']
[2025-02-08T05:06:33.093+0000] {standard_task_runner.py:91} INFO - Job 45: Subtask extract.extract_and_load_to_staging
[2025-02-08T05:06:33.135+0000] {task_command.py:426} INFO - Running <TaskInstance: e_commerce_dw_etl.extract.extract_and_load_to_staging scheduled__2024-11-25T00:00:00+00:00 [running]> on host 366ad6feb228
[2025-02-08T05:06:33.211+0000] {taskinstance.py:2648} INFO - Exporting env vars: AIRFLOW_CTX_DAG_OWNER='***' AIRFLOW_CTX_DAG_ID='e_commerce_dw_etl' AIRFLOW_CTX_TASK_ID='extract.extract_and_load_to_staging' AIRFLOW_CTX_EXECUTION_DATE='2024-11-25T00:00:00+00:00' AIRFLOW_CTX_TRY_NUMBER='1' AIRFLOW_CTX_DAG_RUN_ID='scheduled__2024-11-25T00:00:00+00:00'
[2025-02-08T05:06:33.212+0000] {taskinstance.py:430} INFO - ::endgroup::
[2025-02-08T05:06:33.229+0000] {base.py:84} INFO - Using connection ID 'mysql' for task execution.
[2025-02-08T05:06:36.945+0000] {mysql_operator.py:13} ERROR - Can't connect to mysql database
[2025-02-08T05:06:36.952+0000] {base.py:84} INFO - Using connection ID 'mysql' for task execution.
[2025-02-08T05:06:40.643+0000] {taskinstance.py:441} INFO - ::group::Post task execution logs
[2025-02-08T05:06:40.644+0000] {taskinstance.py:2905} ERROR - Task failed with exception
Traceback (most recent call last):
  File "/home/airflow/.local/lib/python3.10/site-packages/airflow/models/taskinstance.py", line 465, in _execute_task
    result = _execute_callable(context=context, **execute_callable_kwargs)
  File "/home/airflow/.local/lib/python3.10/site-packages/airflow/models/taskinstance.py", line 432, in _execute_callable
    return execute_callable(context=context, **execute_callable_kwargs)
  File "/home/airflow/.local/lib/python3.10/site-packages/airflow/models/baseoperator.py", line 401, in wrapper
    return func(self, *args, **kwargs)
  File "/home/airflow/.local/lib/python3.10/site-packages/airflow/operators/python.py", line 235, in execute
    return_value = self.execute_callable()
  File "/home/airflow/.local/lib/python3.10/site-packages/airflow/operators/python.py", line 252, in execute_callable
    return self.python_callable(*self.op_args, **self.op_kwargs)
  File "/opt/airflow/dags/extract_data.py", line 31, in extract_and_load_to_staging
    df = source_operator.get_data_to_pd(f"SELECT * FROM {table}")
  File "/opt/airflow/plugins/mysql_operator.py", line 16, in get_data_to_pd
    return self.mysqlhook.get_pandas_df(query)
  File "/home/airflow/.local/lib/python3.10/site-packages/airflow/providers/common/sql/hooks/sql.py", line 262, in get_pandas_df
    with closing(self.get_conn()) as conn:
  File "/home/airflow/.local/lib/python3.10/site-packages/airflow/providers/mysql/hooks/mysql.py", line 196, in get_conn
    return MySQLdb.connect(**conn_config)
  File "/home/airflow/.local/lib/python3.10/site-packages/MySQLdb/__init__.py", line 121, in Connect
    return Connection(*args, **kwargs)
  File "/home/airflow/.local/lib/python3.10/site-packages/MySQLdb/connections.py", line 195, in __init__
    super().__init__(*args, **kwargs2)
MySQLdb.OperationalError: (2005, "Unknown server host 'mysql' (-2)")
[2025-02-08T05:06:40.660+0000] {taskinstance.py:1206} INFO - Marking task as FAILED. dag_id=e_commerce_dw_etl, task_id=extract.extract_and_load_to_staging, run_id=scheduled__2024-11-25T00:00:00+00:00, execution_date=20241125T000000, start_date=20250208T050633, end_date=20250208T050640
[2025-02-08T05:06:40.674+0000] {standard_task_runner.py:110} ERROR - Failed to execute job 45 for task extract.extract_and_load_to_staging ((2005, "Unknown server host 'mysql' (-2)"); 290)
[2025-02-08T05:06:40.695+0000] {local_task_job_runner.py:240} INFO - Task exited with return code 1
[2025-02-08T05:06:40.705+0000] {local_task_job_runner.py:222} INFO - ::endgroup::
