[2025-02-08T17:02:57.660+0000] {local_task_job_runner.py:120} INFO - ::group::Pre task execution logs
[2025-02-08T17:02:57.691+0000] {taskinstance.py:2076} INFO - Dependencies all met for dep_context=non-requeueable deps ti=<TaskInstance: hello_dag.create_postgres_table manual__2025-02-08T17:02:55.643262+00:00 [queued]>
[2025-02-08T17:02:57.699+0000] {taskinstance.py:2076} INFO - Dependencies all met for dep_context=requeueable deps ti=<TaskInstance: hello_dag.create_postgres_table manual__2025-02-08T17:02:55.643262+00:00 [queued]>
[2025-02-08T17:02:57.700+0000] {taskinstance.py:2306} INFO - Starting attempt 1 of 1
[2025-02-08T17:02:57.714+0000] {taskinstance.py:2330} INFO - Executing <Task(SQLExecuteQueryOperator): create_postgres_table> on 2025-02-08 17:02:55.643262+00:00
[2025-02-08T17:02:57.718+0000] {standard_task_runner.py:63} INFO - Started process 920 to run task
[2025-02-08T17:02:57.720+0000] {standard_task_runner.py:90} INFO - Running: ['***', 'tasks', 'run', 'hello_dag', 'create_postgres_table', 'manual__2025-02-08T17:02:55.643262+00:00', '--job-id', '140', '--raw', '--subdir', 'DAGS_FOLDER/e_commerce_dw_dag.py', '--cfg-path', '/tmp/tmpxt3sr3la']
[2025-02-08T17:02:57.722+0000] {standard_task_runner.py:91} INFO - Job 140: Subtask create_postgres_table
[2025-02-08T17:02:57.762+0000] {task_command.py:426} INFO - Running <TaskInstance: hello_dag.create_postgres_table manual__2025-02-08T17:02:55.643262+00:00 [running]> on host 452a0b0ca300
[2025-02-08T17:02:57.839+0000] {taskinstance.py:2648} INFO - Exporting env vars: AIRFLOW_CTX_DAG_OWNER='***' AIRFLOW_CTX_DAG_ID='hello_dag' AIRFLOW_CTX_TASK_ID='create_postgres_table' AIRFLOW_CTX_EXECUTION_DATE='2025-02-08T17:02:55.643262+00:00' AIRFLOW_CTX_TRY_NUMBER='1' AIRFLOW_CTX_DAG_RUN_ID='manual__2025-02-08T17:02:55.643262+00:00'
[2025-02-08T17:02:57.840+0000] {taskinstance.py:430} INFO - ::endgroup::
[2025-02-08T17:02:57.852+0000] {sql.py:276} INFO - Executing: 
        CREATE TABLE IF NOT EXISTS my_table (
            id SERIAL PRIMARY KEY,
            name VARCHAR(255) NOT NULL,
            created_at TIMESTAMP DEFAULT CURRENT_TIMESTAMP
        );
        
[2025-02-08T17:02:57.862+0000] {base.py:84} INFO - Using connection ID 'postgres_test' for task execution.
[2025-02-08T17:02:57.868+0000] {logging_mixin.py:188} WARNING - /home/***/.local/lib/python3.10/site-packages/***/models/connection.py:416 AirflowProviderDeprecationWarning: The "schema" arg has been renamed to "database" as it contained the database name.Please use "database" to set the database name.
[2025-02-08T17:02:57.875+0000] {base.py:84} INFO - Using connection ID 'postgres_test' for task execution.
[2025-02-08T17:02:57.891+0000] {taskinstance.py:441} INFO - ::group::Post task execution logs
[2025-02-08T17:02:57.891+0000] {taskinstance.py:2905} ERROR - Task failed with exception
Traceback (most recent call last):
  File "/home/airflow/.local/lib/python3.10/site-packages/airflow/models/taskinstance.py", line 465, in _execute_task
    result = _execute_callable(context=context, **execute_callable_kwargs)
  File "/home/airflow/.local/lib/python3.10/site-packages/airflow/models/taskinstance.py", line 432, in _execute_callable
    return execute_callable(context=context, **execute_callable_kwargs)
  File "/home/airflow/.local/lib/python3.10/site-packages/airflow/models/baseoperator.py", line 401, in wrapper
    return func(self, *args, **kwargs)
  File "/home/airflow/.local/lib/python3.10/site-packages/airflow/providers/common/sql/operators/sql.py", line 282, in execute
    output = hook.run(
  File "/home/airflow/.local/lib/python3.10/site-packages/airflow/providers/common/sql/hooks/sql.py", line 431, in run
    with self._create_autocommit_connection(autocommit) as conn:
  File "/usr/local/lib/python3.10/contextlib.py", line 135, in __enter__
    return next(self.gen)
  File "/home/airflow/.local/lib/python3.10/site-packages/airflow/providers/common/sql/hooks/sql.py", line 551, in _create_autocommit_connection
    with closing(self.get_conn()) as conn:
  File "/home/airflow/.local/lib/python3.10/site-packages/airflow/providers/postgres/hooks/postgres.py", line 175, in get_conn
    self.conn = psycopg2.connect(**conn_args)
  File "/home/airflow/.local/lib/python3.10/site-packages/psycopg2/__init__.py", line 122, in connect
    conn = _connect(dsn, connection_factory=connection_factory, **kwasync)
psycopg2.OperationalError: could not translate host name "host.docker.local" to address: Name or service not known

[2025-02-08T17:02:57.899+0000] {taskinstance.py:1206} INFO - Marking task as FAILED. dag_id=hello_dag, task_id=create_postgres_table, run_id=manual__2025-02-08T17:02:55.643262+00:00, execution_date=20250208T170255, start_date=20250208T170257, end_date=20250208T170257
[2025-02-08T17:02:57.910+0000] {standard_task_runner.py:110} ERROR - Failed to execute job 140 for task create_postgres_table (could not translate host name "host.docker.local" to address: Name or service not known
; 920)
[2025-02-08T17:02:57.933+0000] {local_task_job_runner.py:240} INFO - Task exited with return code 1
[2025-02-08T17:02:57.947+0000] {taskinstance.py:3503} INFO - 0 downstream tasks scheduled from follow-on schedule check
[2025-02-08T17:02:57.950+0000] {local_task_job_runner.py:222} INFO - ::endgroup::
